Workbook

Sheet Key
A1: carrier | B1: aflac | C1: aflac-modified | D1: SBLI | E1: SBLI-Modified | F1: CICA | G1: CICA-GI | H1: gtl | I1: TransAmerica | J1: TransAmerica Graded | K1: Corebridge | L1: amam | M1: amam-graded | N1: amam-return-or-premium | O1: AHL | P1: AHL-Graded | Q1: Royal Neighbors | R1: Royal Neighbors-Graded | S1: Gerber-GI | T1: Mutal of Omaha | U1: Mutual of Omaha-Graded
A2: fee | B2: 48 | C2: 48 | D2: 48 | E2: 48 | F2: 0 | G2: 0 | H2: 48 | I2: 48 | J2: 48 | K2: 24 | L2: 30 | M2: 30 | N2: 30 | O2: 120 | P2: 120 | Q2: 30 | R2: 30 | S2: 11 | T2: 36 | U2: 12
A3: monthly_factor | B3: 0.0875 | C3: 0.0875 | D3: 0.087 | E3: 0.087 | F3: 0 | G3: 0 | H3: 0.08333 | I3: 0.0875 | J3: 0.0875 | K3: 0.0834 | L3: 0.088 | M3: 0.088 | N3: 0.088 | O3: 0.0875 | P3: 0.0875 | Q3: 0.087 | R3: 0.087 | S3: 0.083334 | T3: 0.089 | U3: 0.089
B7: 73 Male Non-Smoker | C7: Monthly Premium
B8: sbli | C8: 59.830292
B9: sbli-mod | C9: 84.876583
B10: aflac | C10: 48.029333
B11: aflace mod | C11: 67.543462
B12: cica | C12: 70.550829
B13: cica gi | C13: 102.27311
B14: trans | C14: 57.152656
B15: trans mod | C15: 66.112246
B16: gtl | C16: 72.94422
B17: corebridge | C17: 74.04
B18: amam | C18: 50.048
B19: amam-grad | C19: 68.090667
... B27: Mutual of Omaha-Graded | C27: 49.05945

Sheet calculations
A1: First Name | B1: Last Name | C1: Phone Number | D1: Age | E1: Dob | F1: Gender | G1: Mailing Address | H1: Birth State: | I1: Height | J1: Weight | K1: Yes | L1: Email | M1: Burial/cremation | N1: Primary beneficiary name | O1: Relation | P1: Secondary beneficiary name | Q1: Relation | R1: Carrier | S1: Coverage | T1: Monthly Premium | U1: 1st premium date | V1: Monthly recurring due date | W1: SSN | X1: Diver's Lisance | Y1: Bank name | Z1: Routing | AA1: Acc | AB1: Health | AC1: Medications | AD1: Doctor name | AE1: Age | AF1: aflac Monthly Quote | AG1: aflac-modified Monthly Quote | AH1: SBLI Monthly Quote | AI1: SBLI-Modified Monthly Quote | AJ1: CICA Monthly Quote | AK1: CICA-GI Monthly Quote | AL1: gtl Monthly Quote | AM1: TransAmerica Monthly Quote | AN1: TransAmerica Graded Monthly Quote | AO1: Corebridge Monthly Quote | AP1: amam Monthly Quote | AQ1: amam-graded Monthly Quote | AR1: amam-return-or-premium Monthly Quote | AS1: AHL Monthly Quote | AT1: AHL-Graded Monthly Quote | AU1: Royal Neighbors Monthly Quote | AV1: Royal Neighbors-Graded Monthly Quote | AW1: Gerber-GI Monthly Quote | AX1: Mutual of Omaha Monthly Quote | AY1: Mutual of Omaha-Graded Monthly Quote | AZ1: AmAm Quote | BA1: AmAm Less Than Current | BB1: GTL Quote | BC1: GTL Less Than Current | BD1: Cheapest Carrier Under Current | BE1: Savings vs Current
A2: Nancy | B2: Franzwa | C2: 3096456388 | D2: 81 | E2: 15297 | F2: Female | G2: 7501-N Villa Lake Dr.Unit 13B Peoria IL 61614 | H2: IN | I2: 5.6 | J2: 145 | K2: No | L2: NA | M2: Cremation | N2: Robert Franzwa ( 12/29/1938 ) | O2: Spouse | P2: NA | Q2: NA | R2: Transamerica ( Standard ) | S2: 2500 | T2: 48.64 | U2: 45933 | V2: 45964 | W2: 315423988 | X2: NA | Y2: SEFCU Bank | Z2: 271183701 | AA2: 104569736 | AB2: Stroke 2023 / High Blood Pressure | AC2: licinopril | AD2: OSF Healthcare Saint Francis | AE2: 84 | AF2: {=IFERROR(_xlfn.LET(_xlpm.rate,INDEX(aflac!$B$2:$E$37,MATCH($AE2,aflac!$A$2:$A$37,0),IF(LOWER(TRIM($F2))="male",IF(LOWER(TRIM($K2))="yes",2,1),IF(LOWER(TRIM($K2))="yes",4,3))),_xlpm.coverage,VALUE(SUBSTITUTE(SUBSTITUTE($S2,"$",""),",","")),_xlpm.base,_xlpm.rate*(_xlpm.coverage/1000),_xlpm.fee,_xlfn.XLOOKUP("aflac",Key!$B$1:$U$1,Key!$B$2:$U$2,0),_xlpm.mf,_xlfn.XLOOKUP("aflac",Key!$B$1:$U$1,Key!$B$3:$U$3,0),IF(_xlpm.mf>0,(_xlpm.base+_xlpm.fee)*_xlpm.mf,(_xlpm.base+_xlpm.fee)/12)),"")} | AG2: {=IFERROR(_xlfn.LET(_xlpm.rate,INDEX('aflac-modified'!$B$2:$C$32,MATCH($AE2,'aflac-modified'!$A$2:$A$32,0),IF(LOWER(TRIM($F2))="male",1,2)),_xlpm.coverage,VALUE(SUBSTITUTE(SUBSTITUTE($S2,"$",""),",","")),_xlpm.base,_xlpm.rate*(_xlpm.coverage/1000),_xlpm.fee,_xlfn.XLOOKUP("aflac-modified",Key!$B$1:$U$1,Key!$B$2:$U$2,0),_xlpm.mf,_xlfn.XLOOKUP("aflac-modified",Key!$B$1:$U$1,Key!$B$3:$U$3,0),IF(_xlpm.mf>0,(_xlpm.base+_xlpm.fee)*_xlpm.mf,(_xlpm.base+_xlpm.fee)/12)),"")} | AH2: {=IFERROR(_xlfn.LET(_xlpm.rate,INDEX(SBLI!$B$2:$E$37,MATCH($AE2,SBLI!$A$2:$A$37,0),IF(LOWER(TRIM($F2))="male",IF(LOWER(TRIM($K2))="yes",2,1),IF(LOWER(TRIM($K2))="yes",4,3))),_xlpm.coverage,VALUE(SUBSTITUTE(SUBSTITUTE($S2,"$",""),",","")),_xlpm.base,_xlpm.rate*(_xlpm.coverage/1000),_xlpm.fee,_xlfn.XLOOKUP("SBLI",Key!$B$1:$U$1,Key!$B$2:$U$2,0),_xlpm.mf,_xlfn.XLOOKUP("SBLI",Key!$B$1:$U$1,Key!$B$3:$U$3,0),IF(_xlpm.mf>0,(_xlpm.base+_xlpm.fee)*_xlpm.mf,(_xlpm.base+_xlpm.fee)/12)),"")} | AI2: {=IFERROR(_xlfn.LET(_xlpm.rate,INDEX('SBLI-Modified'!$B$2:$E$27,MATCH($AE2,'SBLI-Modified'!$A$2:$A$27,0),IF(LOWER(TRIM($F2))="male",IF(LOWER(TRIM($K2))="yes",2,1),IF(LOWER(TRIM($K2))="yes",4,3))),_xlpm.coverage,VALUE(SUBSTITUTE(SUBSTITUTE($S2,"$",""),",","")),_xlpm.base,_xlpm.rate*(_xlpm.coverage/1000),_xlpm.fee,_xlfn.XLOOKUP("SBLI-Modified",Key!$B$1:$U$1,Key!$B$2:$U$2,0),_xlpm.mf,_xlfn.XLOOKUP("SBLI-Modified",Key!$B$1:$U$1,Key!$B$3:$U$3,0),IF(_xlpm.mf>0,(_xlpm.base+_xlpm.fee)*_xlpm.mf,(_xlpm.base+_xlpm.fee)/12)),"")} | AJ2: {=IFERROR(_xlfn.LET(_xlpm.rate,INDEX(CICA!$B$2:$C$42,MATCH($AE2,CICA!$A$2:$A$42,0),IF(LOWER(TRIM($F2))="male",1,2)),_xlpm.coverage,VALUE(SUBSTITUTE(SUBSTITUTE($S2,"$",""),",","")),_xlpm.base,_xlpm.rate*(_xlpm.coverage/1000),_xlpm.fee,_xlfn.XLOOKUP("CICA",Key!$B$1:$U$1,Key!$B$2:$U$2,0),_xlpm.mf,_xlfn.XLOOKUP("CICA",Key!$B$1:$U$1,Key!$B$3:$U$3,0),IF(_xlpm.mf>0,(_xlpm.base+_xlpm.fee)*_xlpm.mf,(_xlpm.base+_xlpm.fee)/12)),"")} | AK2: {=IFERROR(_xlfn.LET(_xlpm.rate,INDEX('CICA-GI'!$B$2:$C$47,MATCH($AE2,'CICA-GI'!$A$2:$A$47,0),IF(LOWER(TRIM($F2))="male",1,2)),_xlpm.coverage,VALUE(SUBSTITUTE(SUBSTITUTE($S2,"$",""),",","")),_xlpm.base,_xlpm.rate*(_xlpm.coverage/1000),_xlpm.fee,_xlfn.XLOOKUP("CICA-GI",Key!$B$1:$U$1,Key!$B$2:$U$2,0),_xlpm.mf,_xlfn.XLOOKUP("CICA-GI",Key!$B$1:$U$1,Key!$B$3:$U$3,0),IF(_xlpm.mf>0,(_xlpm.base+_xlpm.fee)*_xlpm.mf,(_xlpm.base+_xlpm.fee)/12)),"")} | AL2: {=IFERROR(_xlfn.LET(_xlpm.rate,INDEX(gtl!$B$2:$C$52,MATCH($AE2,gtl!$A$2:$A$52,0),IF(LOWER(TRIM($F2))="male",1,2)),_xlpm.coverage,VALUE(SUBSTITUTE(SUBSTITUTE($S2,"$",""),",","")),_xlpm.base,_xlpm.rate*(_xlpm.coverage/1000),_xlpm.fee,_xlfn.XLOOKUP("gtl",Key!$B$1:$U$1,Key!$B$2:$U$2,0),_xlpm.mf,_xlfn.XLOOKUP("gtl",Key!$B$1:$U$1,Key!$B$3:$U$3,0),IF(_xlpm.mf>0,(_xlpm.base+_xlpm.fee)*_xlpm.mf,(_xlpm.base+_xlpm.fee)/12)),"")} | AM2: {=IFERROR(_xlfn.LET(_xlpm.rate,INDEX(TransAmerica!$B$2:$E$69,MATCH($AE2,TransAmerica!$A$2:$A$69,0),IF(LOWER(TRIM($F2))="male",IF(LOWER(TRIM($K2))="yes",2,1),IF(LOWER(TRIM($K2))="yes",4,3))),_xlpm.coverage,VALUE(SUBSTITUTE(SUBSTITUTE($S2,"$",""),",","")),_xlpm.base,_xlpm.rate*(_xlpm.coverage/1000),_xlpm.fee,_xlfn.XLOOKUP("TransAmerica",Key!$B$1:$U$1,Key!$B$2:$U$2,0),_xlpm.mf,_xlfn.XLOOKUP("TransAmerica",Key!$B$1:$U$1,Key!$B$3:$U$3,0),IF(_xlpm.mf>0,(_xlpm.base+_xlpm.fee)*_xlpm.mf,(_xlpm.base+_xlpm.fee)/12)),"")} | AN2: {=IFERROR(_xlfn.LET(_xlpm.rate,INDEX('TransAmerica Graded'!$B$2:$E$64,MATCH($AE2,'TransAmerica Graded'!$A$2:$A$64,0),IF(LOWER(TRIM($F2))="male",IF(LOWER(TRIM($K2))="yes",2,1),IF(LOWER(TRIM($K2))="yes",4,3))),_xlpm.coverage,VALUE(SUBSTITUTE(SUBSTITUTE($S2,"$",""),",","")),_xlpm.base,_xlpm.rate*(_xlpm.coverage/1000),_xlpm.fee,_xlfn.XLOOKUP("TransAmerica Graded",Key!$B$1:$U$1,Key!$B$2:$U$2,0),_xlpm.mf,_xlfn.XLOOKUP("TransAmerica Graded",Key!$B$1:$U$1,Key!$B$3:$U$3,0),IF(_xlpm.mf>0,(_xlpm.base+_xlpm.fee)*_xlpm.mf,(_xlpm.base+_xlpm.fee)/12)),"")} | AO2: {=IFERROR(_xlfn.LET(_xlpm.rate,INDEX(Corebridge!$B$2:$C$32,MATCH($AE2,Corebridge!$A$2:$A$32,0),IF(LOWER(TRIM($F2))="male",1,2)),_xlpm.coverage,VALUE(SUBSTITUTE(SUBSTITUTE($S2,"$",""),",","")),_xlpm.base,_xlpm.rate*(_xlpm.coverage/1000),_xlpm.fee,_xlfn.XLOOKUP("Corebridge",Key!$B$1:$U$1,Key!$B$2:$U$2,0),_xlpm.mf,_xlfn.XLOOKUP("Corebridge",Key!$B$1:$U$1,Key!$B$3:$U$3,0),IF(_xlpm.mf>0,(_xlpm.base+_xlpm.fee)*_xlpm.mf,(_xlpm.base+_xlpm.fee)/12)),"")} | AP2: {=IFERROR(_xlfn.LET(_xlpm.rate,INDEX(amam!$B$2:$E$37,MATCH($AE2,amam!$A$2:$A$37,0),IF(LOWER(TRIM($F2))="male",IF(LOWER(TRIM($K2))="yes",2,1),IF(LOWER(TRIM($K2))="yes",4,3))),_xlpm.coverage,VALUE(SUBSTITUTE(SUBSTITUTE($S2,"$",""),",","")),_xlpm.base,_xlpm.rate*(_xlpm.coverage/1000),_xlpm.fee,_xlfn.XLOOKUP("amam",Key!$B$1:$U$1,Key!$B$2:$U$2,0),_xlpm.mf,_xlfn.XLOOKUP("amam",Key!$B$1:$U$1,Key!$B$3:$U$3,0),IF(_xlpm.mf>0,(_xlpm.base+_xlpm.fee)*_xlpm.mf,(_xlpm.base+_xlpm.fee)/12)),"")} | AQ2: {=IFERROR(_xlfn.LET(_xlpm.rate,INDEX('amam-graded'!$B$2:$E$37,MATCH($AE2,'amam-graded'!$A$2:$A$37,0),IF(LOWER(TRIM($F2))="male",IF(LOWER(TRIM($K2))="yes",2,1),IF(LOWER(TRIM($K2))="yes",4,3))),_xlpm.coverage,VALUE(SUBSTITUTE(SUBSTITUTE($S2,"$",""),",","")),_xlpm.base,_xlpm.rate*(_xlpm.coverage/1000),_xlpm.fee,_xlfn.XLOOKUP("amam-graded",Key!$B$1:$U$1,Key!$B$2:$U$2,0),_xlpm.mf,_xlfn.XLOOKUP("amam-graded",Key!$B$1:$U$1,Key!$B$3:$U$3,0),IF(_xlpm.mf>0,(_xlpm.base+_xlpm.fee)*_xlpm.mf,(_xlpm.base+_xlpm.fee)/12)),"")} | AR2: {=IFERROR(_xlfn.LET(_xlpm.rate,INDEX('amam-return-or-premium'!$B$2:$E$37,MATCH($AE2,'amam-return-or-premium'!$A$2:$A$37,0),IF(LOWER(TRIM($F2))="male",IF(LOWER(TRIM($K2))="yes",2,1),IF(LOWER(TRIM($K2))="yes",4,3))),_xlpm.coverage,VALUE(SUBSTITUTE(SUBSTITUTE($S2,"$",""),",","")),_xlpm.base,_xlpm.rate*(_xlpm.coverage/1000),_xlpm.fee,_xlfn.XLOOKUP("amam-return-or-premium",Key!$B$1:$U$1,Key!$B$2:$U$2,0),_xlpm.mf,_xlfn.XLOOKUP("amam-return-or-premium",Key!$B$1:$U$1,Key!$B$3:$U$3,0),IF(_xlpm.mf>0,(_xlpm.base+_xlpm.fee)*_xlpm.mf,(_xlpm.base+_xlpm.fee)/12)),"")} | AS2: {=IFERROR(_xlfn.LET(_xlpm.rate,INDEX(AHL!$B$2:$E$37,MATCH($AE2,AHL!$A$2:$A$37,0),IF(LOWER(TRIM($F2))="male",IF(LOWER(TRIM($K2))="yes",2,1),IF(LOWER(TRIM($K2))="yes",4,3))),_xlpm.coverage,VALUE(SUBSTITUTE(SUBSTITUTE($S2,"$",""),",","")),_xlpm.base,_xlpm.rate*(_xlpm.coverage/1000),_xlpm.fee,_xlfn.XLOOKUP("AHL",Key!$B$1:$U$1,Key!$B$2:$U$2,0),_xlpm.mf,_xlfn.XLOOKUP("AHL",Key!$B$1:$U$1,Key!$B$3:$U$3,0),IF(_xlpm.mf>0,(_xlpm.base+_xlpm.fee)*_xlpm.mf,(_xlpm.base+_xlpm.fee)/12)),"")} | AT2: {=IFERROR(_xlfn.LET(_xlpm.rate,INDEX('AHL-Graded'!$B$2:$E$32,MATCH($AE2,'AHL-Graded'!$A$2:$A$32,0),IF(LOWER(TRIM($F2))="male",IF(LOWER(TRIM($K2))="yes",2,1),IF(LOWER(TRIM($K2))="yes",4,3))),_xlpm.coverage,VALUE(SUBSTITUTE(SUBSTITUTE($S2,"$",""),",","")),_xlpm.base,_xlpm.rate*(_xlpm.coverage/1000),_xlpm.fee,_xlfn.XLOOKUP("AHL-Graded",Key!$B$1:$U$1,Key!$B$2:$U$2,0),_xlpm.mf,_xlfn.XLOOKUP("AHL-Graded",Key!$B$1:$U$1,Key!$B$3:$U$3,0),IF(_xlpm.mf>0,(_xlpm.base+_xlpm.fee)*_xlpm.mf,(_xlpm.base+_xlpm.fee)/12)),"")} | AU2: {=IFERROR(_xlfn.LET(_xlpm.rate,INDEX('Royal Neighbors'!$B$2:$E$37,MATCH($AE2,'Royal Neighbors'!$A$2:$A$37,0),IF(LOWER(TRIM($F2))="male",IF(LOWER(TRIM($K2))="yes",2,1),IF(LOWER(TRIM($K2))="yes",4,3))),_xlpm.coverage,VALUE(SUBSTITUTE(SUBSTITUTE($S2,"$",""),",","")),_xlpm.base,_xlpm.rate*(_xlpm.coverage/1000),_xlpm.fee,_xlfn.XLOOKUP("Royal Neighbors",Key!$B$1:$U$1,Key!$B$2:$U$2,0),_xlpm.mf,_xlfn.XLOOKUP("Royal Neighbors",Key!$B$1:$U$1,Key!$B$3:$U$3,0),IF(_xlpm.mf>0,(_xlpm.base+_xlpm.fee)*_xlpm.mf,(_xlpm.base+_xlpm.fee)/12)),"")} | AV2: {=IFERROR(_xlfn.LET(_xlpm.rate,INDEX('Royal Neighbors-Graded'!$B$2:$E$37,MATCH($AE2,'Royal Neighbors-Graded'!$A$2:$A$37,0),IF(LOWER(TRIM($F2))="male",IF(LOWER(TRIM($K2))="yes",2,1),IF(LOWER(TRIM($K2))="yes",4,3))),_xlpm.coverage,VALUE(SUBSTITUTE(SUBSTITUTE($S2,"$",""),",","")),_xlpm.base,_xlpm.rate*(_xlpm.coverage/1000),_xlpm.fee,_xlfn.XLOOKUP("Royal Neighbors-Graded",Key!$B$1:$U$1,Key!$B$2:$U$2,0),_xlpm.mf,_xlfn.XLOOKUP("Royal Neighbors-Graded",Key!$B$1:$U$1,Key!$B$3:$U$3,0),IF(_xlpm.mf>0,(_xlpm.base+_xlpm.fee)*_xlpm.mf,(_xlpm.base+_xlpm.fee)/12)),"")} | AW2: {=IFERROR(_xlfn.LET(_xlpm.rate,INDEX('Gerber-GI'!$B$2:$C$32,MATCH($AE2,'Gerber-GI'!$A$2:$A$32,0),IF(LOWER(TRIM($F2))="male",1,2)),_xlpm.coverage,VALUE(SUBSTITUTE(SUBSTITUTE($S2,"$",""),",","")),_xlpm.base,_xlpm.rate*(_xlpm.coverage/1000),_xlpm.fee,_xlfn.XLOOKUP("Gerber-GI",Key!$B$1:$U$1,Key!$B$2:$U$2,0),_xlpm.mf,_xlfn.XLOOKUP("Gerber-GI",Key!$B$1:$U$1,Key!$B$3:$U$3,0),IF(_xlpm.mf>0,(_xlpm.base+_xlpm.fee)*_xlpm.mf,(_xlpm.base+_xlpm.fee)/12)),"")} | AX2: {=IFERROR(_xlfn.LET(_xlpm.rate,INDEX('Mutual of Omaha'!$B$2:$E$42,MATCH($AE2,'Mutual of Omaha'!$A$2:$A$42,0),IF(LOWER(TRIM($F2))="male",IF(LOWER(TRIM($K2))="yes",2,1),IF(LOWER(TRIM($K2))="yes",4,3))),_xlpm.coverage,VALUE(SUBSTITUTE(SUBSTITUTE($S2,"$",""),",","")),_xlpm.base,_xlpm.rate*(_xlpm.coverage/1000),_xlpm.fee,_xlfn.XLOOKUP("Mutal of Omaha",Key!$B$1:$U$1,Key!$B$2:$U$2,0),_xlpm.mf,_xlfn.XLOOKUP("Mutal of Omaha",Key!$B$1:$U$1,Key!$B$3:$U$3,0),IF(_xlpm.mf>0,(_xlpm.base+_xlpm.fee)*_xlpm.mf,(_xlpm.base+_xlpm.fee)/12)),"")} | AY2: {=IFERROR(_xlfn.LET(_xlpm.rate,INDEX('Mutual of Omaha-Graded'!$B$2:$E$37,MATCH($AE2,'Mutual of Omaha-Graded'!$A$2:$A$37,0),IF(LOWER(TRIM($F2))="male",IF(LOWER(TRIM($K2))="yes",2,1),IF(LOWER(TRIM($K2))="yes",4,3))),_xlpm.coverage,VALUE(SUBSTITUTE(SUBSTITUTE($S2,"$",""),",","")),_xlpm.base,_xlpm.rate*(_xlpm.coverage/1000),_xlpm.fee,_xlfn.XLOOKUP("Mutual of Omaha-Graded",Key!$B$1:$U$1,Key!$B$2:$U$2,0),_xlpm.mf,_xlfn.XLOOKUP("Mutual of Omaha-Graded",Key!$B$1:$U$1,Key!$B$3:$U$3,0),IF(_xlpm.mf>0,(_xlpm.base+_xlpm.fee)*_xlpm.mf,(_xlpm.base+_xlpm.fee)/12)),"")} | AZ2: =AP2 | BA2: =IFERROR(IF(AND(AP2>0,AP2<VALUE(SUBSTITUTE(SUBSTITUTE($T2,"$",""),",",""))),VALUE(SUBSTITUTE(SUBSTITUTE($T2,"$",""),",",""))-AP2,""),"") | BB2: =AL2 | BC2: =IFERROR(IF(AND(AL2>0,AL2<VALUE(SUBSTITUTE(SUBSTITUTE($T2,"$",""),",",""))),VALUE(SUBSTITUTE(SUBSTITUTE($T2,"$",""),",",""))-AL2,""),"") | BD2: {=IFERROR(_xlfn.LET(_xlpm.current,VALUE(SUBSTITUTE(SUBSTITUTE($T2,"$",""),",","")),_xlpm.quotes,AF2:AY2,_xlpm.lowest,_xlfn.MINIFS(_xlpm.quotes,_xlpm.quotes,"<"&_xlpm.current,_xlpm.quotes,">0"),IF(_xlpm.lowest="","",SUBSTITUTE(INDEX($AF$1:$AY$1,1,MATCH(_xlpm.lowest,_xlpm.quotes,0))," Monthly Quote",""))),"")} | BE2: {=IFERROR(_xlfn.LET(_xlpm.current,VALUE(SUBSTITUTE(SUBSTITUTE($T2,"$",""),",","")),_xlpm.quotes,AF2:AY2,_xlpm.lowest,_xlfn.MINIFS(_xlpm.quotes,_xlpm.quotes,"<"&_xlpm.current,_xlpm.quotes,">0"),IF(_xlpm.lowest="","",_xlpm.current-_xlpm.lowest)),"")}
A3: Margie R | B3: Wiltbank | C3: 8327106495 | D3: 84 | E3: 14988 | F3: Female | G3: 7706 Pebble Run Ct Houston TX 77095 | H3: TX | I3: 5.6 | J3: 165 | K3: No | M3: Cremation | N3: Rodrick Davis : (66) | O3: Son | R3: Transamerica | S3: 5000 | T3: 76.17 | U3: 45966 | V3: 45996 | W3: 465643045 | Y3: FIRST COMMUNITY BANK | Z3: Card : 4777480009752095 | AA3: EXP 01/28 CVC 268 | AB3: High blood Pressure knee surgery | AC3: 4 pills | AD3: NO | AE3: 85 | AF3: {=IFERROR(_xlfn.LET(_xlpm.rate,INDEX(aflac!$B$2:$E$37,MATCH($AE3,aflac!$A$2:$A$37,0),IF(LOWER(TRIM($F3))="male",IF(LOWER(TRIM($K3))="yes",2,1),IF(LOWER(TRIM($K3))="yes",4,3))),_xlpm.coverage,VALUE(SUBSTITUTE(SUBSTITUTE($S3,"$",""),",","")),_xlpm.base,_xlpm.rate*(_xlpm.coverage/1000),_xlpm.fee,_xlfn.XLOOKUP("aflac",Key!$B$1:$U$1,Key!$B$2:$U$2,0),_xlpm.mf,_xlfn.XLOOKUP("aflac",Key!$B$1:$U$1,Key!$B$3:$U$3,0),IF(_xlpm.mf>0,(_xlpm.base+_xlpm.fee)*_xlpm.mf,(_xlpm.base+_xlpm.fee)/12)),"")} | AG3: {=IFERROR(_xlfn.LET(_xlpm.rate,INDEX('aflac-modified'!$B$2:$C$32,MATCH($AE3,'aflac-modified'!$A$2:$A$32,0),IF(LOWER(TRIM($F3))="male",1,2)),_xlpm.coverage,VALUE(SUBSTITUTE(SUBSTITUTE($S3,"$",""),",","")),_xlpm.base,_xlpm.rate*(_xlpm.coverage/1000),_xlpm.fee,_xlfn.XLOOKUP("aflac-modified",Key!$B$1:$U$1,Key!$B$2:$U$2,0),_xlpm.mf,_xlfn.XLOOKUP("aflac-modified",Key!$B$1:$U$1,Key!$B$3:$U$3,0),IF(_xlpm.mf>0,(_xlpm.base+_xlpm.fee)*_xlpm.mf,(_xlpm.base+_xlpm.fee)/12)),"")} | AH3: {=IFERROR(_xlfn.LET(_xlpm.rate,INDEX(SBLI!$B$2:$E$37,MATCH($AE3,SBLI!$A$2:$A$37,0),IF(LOWER(TRIM($F3))="male",IF(LOWER(TRIM($K3))="yes",2,1),IF(LOWER(TRIM($K3))="yes",4,3))),_xlpm.coverage,VALUE(SUBSTITUTE(SUBSTITUTE($S3,"$",""),",","")),_xlpm.base,_xlpm.rate*(_xlpm.coverage/1000),_xlpm.fee,_xlfn.XLOOKUP("SBLI",Key!$B$1:$U$1,Key!$B$2:$U$2,0),_xlpm.mf,_xlfn.XLOOKUP("SBLI",Key!$B$1:$U$1,Key!$B$3:$U$3,0),IF(_xlpm.mf>0,(_xlpm.base+_xlpm.fee)*_xlpm.mf,(_xlpm.base+_xlpm.fee)/12)),"")} | AI3: {=IFERROR(_xlfn.LET(_xlpm.rate,INDEX('SBLI-Modified'!$B$2:$E$27,MATCH($AE3,'SBLI-Modified'!$A$2:$A$27,0),IF(LOWER(TRIM($F3))="male",IF(LOWER(TRIM($K3))="yes",2,1),IF(LOWER(TRIM($K3))="yes",4,3))),_xlpm.coverage,VALUE(SUBSTITUTE(SUBSTITUTE($S3,"$",""),",","")),_xlpm.base,_xlpm.rate*(_xlpm.coverage/1000),_xlpm.fee,_xlfn.XLOOKUP("SBLI-Modified",Key!$B$1:$U$1,Key!$B$2:$U$2,0),_xlpm.mf,_xlfn.XLOOKUP("SBLI-Modified",Key!$B$1:$U$1,Key!$B$3:$U$3,0),IF(_xlpm.mf>0,(_xlpm.base+_xlpm.fee)*_xlpm.mf,(_xlpm.base+_xlpm.fee)/12)),"")} | AJ3: {=IFERROR(_xlfn.LET(_xlpm.rate,INDEX(CICA!$B$2:$C$42,MATCH($AE3,CICA!$A$2:$A$42,0),IF(LOWER(TRIM($F3))="male",1,2)),_xlpm.coverage,VALUE(SUBSTITUTE(SUBSTITUTE($S3,"$",""),",","")),_xlpm.base,_xlpm.rate*(_xlpm.coverage/1000),_xlpm.fee,_xlfn.XLOOKUP("CICA",Key!$B$1:$U$1,Key!$B$2:$U$2,0),_xlpm.mf,_xlfn.XLOOKUP("CICA",Key!$B$1:$U$1,Key!$B$3:$U$3,0),IF(_xlpm.mf>0,(_xlpm.base+_xlpm.fee)*_xlpm.mf,(_xlpm.base+_xlpm.fee)/12)),"")} | AK3: {=IFERROR(_xlfn.LET(_xlpm.rate,INDEX('CICA-GI'!$B$2:$C$47,MATCH($AE3,'CICA-GI'!$A$2:$A$47,0),IF(LOWER(TRIM($F3))="male",1,2)),_xlpm.coverage,VALUE(SUBSTITUTE(SUBSTITUTE($S3,"$",""),",","")),_xlpm.base,_xlpm.rate*(_xlpm.coverage/1000),_xlpm.fee,_xlfn.XLOOKUP("CICA-GI",Key!$B$1:$U$1,Key!$B$2:$U$2,0),_xlpm.mf,_xlfn.XLOOKUP("CICA-GI",Key!$B$1:$U$1,Key!$B$3:$U$3,0),IF(_xlpm.mf>0,(_xlpm.base+_xlpm.fee)*_xlpm.mf,(_xlpm.base+_xlpm.fee)/12)),"")} | AL3: {=IFERROR(_xlfn.LET(_xlpm.rate,INDEX(gtl!$B$2:$C$52,MATCH($AE3,gtl!$A$2:$A$52,0),IF(LOWER(TRIM($F3))="male",1,2)),_xlpm.coverage,VALUE(SUBSTITUTE(SUBSTITUTE($S3,"$",""),",","")),_xlpm.base,_xlpm.rate*(_xlpm.coverage/1000),_xlpm.fee,_xlfn.XLOOKUP("gtl",Key!$B$1:$U$1,Key!$B$2:$U$2,0),_xlpm.mf,_xlfn.XLOOKUP("gtl",Key!$B$1:$U$1,Key!$B$3:$U$3,0),IF(_xlpm.mf>0,(_xlpm.base+_xlpm.fee)*_xlpm.mf,(_xlpm.base+_xlpm.fee)/12)),"")} | AM3: {=IFERROR(_xlfn.LET(_xlpm.rate,INDEX(TransAmerica!$B$2:$E$69,MATCH($AE3,TransAmerica!$A$2:$A$69,0),IF(LOWER(TRIM($F3))="male",IF(LOWER(TRIM($K3))="yes",2,1),IF(LOWER(TRIM($K3))="yes",4,3))),_xlpm.coverage,VALUE(SUBSTITUTE(SUBSTITUTE($S3,"$",""),",","")),_xlpm.base,_xlpm.rate*(_xlpm.coverage/1000),_xlpm.fee,_xlfn.XLOOKUP("TransAmerica",Key!$B$1:$U$1,Key!$B$2:$U$2,0),_xlpm.mf,_xlfn.XLOOKUP("TransAmerica",Key!$B$1:$U$1,Key!$B$3:$U$3,0),IF(_xlpm.mf>0,(_xlpm.base+_xlpm.fee)*_xlpm.mf,(_xlpm.base+_xlpm.fee)/12)),"")} | AN3: {=IFERROR(_xlfn.LET(_xlpm.rate,INDEX('TransAmerica Graded'!$B$2:$E$64,MATCH($AE3,'TransAmerica Graded'!$A$2:$A$64,0),IF(LOWER(TRIM($F3))="male",IF(LOWER(TRIM($K3))="yes",2,1),IF(LOWER(TRIM($K3))="yes",4,3))),_xlpm.coverage,VALUE(SUBSTITUTE(SUBSTITUTE($S3,"$",""),",","")),_xlpm.base,_xlpm.rate*(_xlpm.coverage/1000),_xlpm.fee,_xlfn.XLOOKUP("TransAmerica Graded",Key!$B$1:$U$1,Key!$B$2:$U$2,0),_xlpm.mf,_xlfn.XLOOKUP("TransAmerica Graded",Key!$B$1:$U$1,Key!$B$3:$U$3,0),IF(_xlpm.mf>0,(_xlpm.base+_xlpm.fee)*_xlpm.mf,(_xlpm.base+_xlpm.fee)/12)),"")} | AO3: {=IFERROR(_xlfn.LET(_xlpm.rate,INDEX(Corebridge!$B$2:$C$32,MATCH($AE3,Corebridge!$A$2:$A$32,0),IF(LOWER(TRIM($F3))="male",1,2)),_xlpm.coverage,VALUE(SUBSTITUTE(SUBSTITUTE($S3,"$",""),",","")),_xlpm.base,_xlpm.rate*(_xlpm.coverage/1000),_xlpm.fee,_xlfn.XLOOKUP("Corebridge",Key!$B$1:$U$1,Key!$B$2:$U$2,0),_xlpm.mf,_xlfn.XLOOKUP("Corebridge",Key!$B$1:$U$1,Key!$B$3:$U$3,0),IF(_xlpm.mf>0,(_xlpm.base+_xlpm.fee)*_xlpm.mf,(_xlpm.base+_xlpm.fee)/12)),"")} | AP3: {=IFERROR(_xlfn.LET(_xlpm.rate,INDEX(amam!$B$2:$E$37,MATCH($AE3,amam!$A$2:$A$37,0),IF(LOWER(TRIM($F3))="male",IF(LOWER(TRIM($K3))="yes",2,1),IF(LOWER(TRIM($K3))="yes",4,3))),_xlpm.coverage,VALUE(SUBSTITUTE(SUBSTITUTE($S3,"$",""),",","")),_xlpm.base,_xlpm.rate*(_xlpm.coverage/1000),_xlpm.fee,_xlfn.XLOOKUP("amam",Key!$B$1:$U$1,Key!$B$2:$U$2,0),_xlpm.mf,_xlfn.XLOOKUP("amam",Key!$B$1:$U$1,Key!$B$3:$U$3,0),IF(_xlpm.mf>0,(_xlpm.base+_xlpm.fee)*_xlpm.mf,(_xlpm.base+_xlpm.fee)/12)),"")} | AQ3: {=IFERROR(_xlfn.LET(_xlpm.rate,INDEX('amam-graded'!$B$2:$E$37,MATCH($AE3,'amam-graded'!$A$2:$A$37,0),IF(LOWER(TRIM($F3))="male",IF(LOWER(TRIM($K3))="yes",2,1),IF(LOWER(TRIM($K3))="yes",4,3))),_xlpm.coverage,VALUE(SUBSTITUTE(SUBSTITUTE($S3,"$",""),",","")),_xlpm.base,_xlpm.rate*(_xlpm.coverage/1000),_xlpm.fee,_xlfn.XLOOKUP("amam-graded",Key!$B$1:$U$1,Key!$B$2:$U$2,0),_xlpm.mf,_xlfn.XLOOKUP("amam-graded",Key!$B$1:$U$1,Key!$B$3:$U$3,0),IF(_xlpm.mf>0,(_xlpm.base+_xlpm.fee)*_xlpm.mf,(_xlpm.base+_xlpm.fee)/12)),"")} | AR3: {=IFERROR(_xlfn.LET(_xlpm.rate,INDEX('amam-return-or-premium'!$B$2:$E$37,MATCH($AE3,'amam-return-or-premium'!$A$2:$A$37,0),IF(LOWER(TRIM($F3))="male",IF(LOWER(TRIM($K3))="yes",2,1),IF(LOWER(TRIM($K3))="yes",4,3))),_xlpm.coverage,VALUE(SUBSTITUTE(SUBSTITUTE($S3,"$",""),",","")),_xlpm.base,_xlpm.rate*(_xlpm.coverage/1000),_xlpm.fee,_xlfn.XLOOKUP("amam-return-or-premium",Key!$B$1:$U$1,Key!$B$2:$U$2,0),_xlpm.mf,_xlfn.XLOOKUP("amam-return-or-premium",Key!$B$1:$U$1,Key!$B$3:$U$3,0),IF(_xlpm.mf>0,(_xlpm.base+_xlpm.fee)*_xlpm.mf,(_xlpm.base+_xlpm.fee)/12)),"")} | AS3: {=IFERROR(_xlfn.LET(_xlpm.rate,INDEX(AHL!$B$2:$E$37,MATCH($AE3,AHL!$A$2:$A$37,0),IF(LOWER(TRIM($F3))="male",IF(LOWER(TRIM($K3))="yes",2,1),IF(LOWER(TRIM($K3))="yes",4,3))),_xlpm.coverage,VALUE(SUBSTITUTE(SUBSTITUTE($S3,"$",""),",","")),_xlpm.base,_xlpm.rate*(_xlpm.coverage/1000),_xlpm.fee,_xlfn.XLOOKUP("AHL",Key!$B$1:$U$1,Key!$B$2:$U$2,0),_xlpm.mf,_xlfn.XLOOKUP("AHL",Key!$B$1:$U$1,Key!$B$3:$U$3,0),IF(_xlpm.mf>0,(_xlpm.base+_xlpm.fee)*_xlpm.mf,(_xlpm.base+_xlpm.fee)/12)),"")} | AT3: {=IFERROR(_xlfn.LET(_xlpm.rate,INDEX('AHL-Graded'!$B$2:$E$32,MATCH($AE3,'AHL-Graded'!$A$2:$A$32,0),IF(LOWER(TRIM($F3))="male",IF(LOWER(TRIM($K3))="yes",2,1),IF(LOWER(TRIM($K3))="yes",4,3))),_xlpm.coverage,VALUE(SUBSTITUTE(SUBSTITUTE($S3,"$",""),",","")),_xlpm.base,_xlpm.rate*(_xlpm.coverage/1000),_xlpm.fee,_xlfn.XLOOKUP("AHL-Graded",Key!$B$1:$U$1,Key!$B$2:$U$2,0),_xlpm.mf,_xlfn.XLOOKUP("AHL-Graded",Key!$B$1:$U$1,Key!$B$3:$U$3,0),IF(_xlpm.mf>0,(_xlpm.base+_xlpm.fee)*_xlpm.mf,(_xlpm.base+_xlpm.fee)/12)),"")} | AU3: {=IFERROR(_xlfn.LET(_xlpm.rate,INDEX('Royal Neighbors'!$B$2:$E$37,MATCH($AE3,'Royal Neighbors'!$A$2:$A$37,0),IF(LOWER(TRIM($F3))="male",IF(LOWER(TRIM($K3))="yes",2,1),IF(LOWER(TRIM($K3))="yes",4,3))),_xlpm.coverage,VALUE(SUBSTITUTE(SUBSTITUTE($S3,"$",""),",","")),_xlpm.base,_xlpm.rate*(_xlpm.coverage/1000),_xlpm.fee,_xlfn.XLOOKUP("Royal Neighbors",Key!$B$1:$U$1,Key!$B$2:$U$2,0),_xlpm.mf,_xlfn.XLOOKUP("Royal Neighbors",Key!$B$1:$U$1,Key!$B$3:$U$3,0),IF(_xlpm.mf>0,(_xlpm.base+_xlpm.fee)*_xlpm.mf,(_xlpm.base+_xlpm.fee)/12)),"")} | AV3: {=IFERROR(_xlfn.LET(_xlpm.rate,INDEX('Royal Neighbors-Graded'!$B$2:$E$37,MATCH($AE3,'Royal Neighbors-Graded'!$A$2:$A$37,0),IF(LOWER(TRIM($F3))="male",IF(LOWER(TRIM($K3))="yes",2,1),IF(LOWER(TRIM($K3))="yes",4,3))),_xlpm.coverage,VALUE(SUBSTITUTE(SUBSTITUTE($S3,"$",""),",","")),_xlpm.base,_xlpm.rate*(_xlpm.coverage/1000),_xlpm.fee,_xlfn.XLOOKUP("Royal Neighbors-Graded",Key!$B$1:$U$1,Key!$B$2:$U$2,0),_xlpm.mf,_xlfn.XLOOKUP("Royal Neighbors-Graded",Key!$B$1:$U$1,Key!$B$3:$U$3,0),IF(_xlpm.mf>0,(_xlpm.base+_xlpm.fee)*_xlpm.mf,(_xlpm.base+_xlpm.fee)/12)),"")} | AW3: {=IFERROR(_xlfn.LET(_xlpm.rate,INDEX('Gerber-GI'!$B$2:$C$32,MATCH($AE3,'Gerber-GI'!$A$2:$A$32,0),IF(LOWER(TRIM($F3))="male",1,2)),_xlpm.coverage,VALUE(SUBSTITUTE(SUBSTITUTE($S3,"$",""),",","")),_xlpm.base,_xlpm.rate*(_xlpm.coverage/1000),_xlpm.fee,_xlfn.XLOOKUP("Gerber-GI",Key!$B$1:$U$1,Key!$B$2:$U$2,0),_xlpm.mf,_xlfn.XLOOKUP("Gerber-GI",Key!$B$1:$U$1,Key!$B$3:$U$3,0),IF(_xlpm.mf>0,(_xlpm.base+_xlpm.fee)*_xlpm.mf,(_xlpm.base+_xlpm.fee)/12)),"")} | AX3: {=IFERROR(_xlfn.LET(_xlpm.rate,INDEX('Mutual of Omaha'!$B$2:$E$42,MATCH($AE3,'Mutual of Omaha'!$A$2:$A$42,0),IF(LOWER(TRIM($F3))="male",IF(LOWER(TRIM($K3))="yes",2,1),IF(LOWER(TRIM($K3))="yes",4,3))),_xlpm.coverage,VALUE(SUBSTITUTE(SUBSTITUTE($S3,"$",""),",","")),_xlpm.base,_xlpm.rate*(_xlpm.coverage/1000),_xlpm.fee,_xlfn.XLOOKUP("Mutal of Omaha",Key!$B$1:$U$1,Key!$B$2:$U$2,0),_xlpm.mf,_xlfn.XLOOKUP("Mutal of Omaha",Key!$B$1:$U$1,Key!$B$3:$U$3,0),IF(_xlpm.mf>0,(_xlpm.base+_xlpm.fee)*_xlpm.mf,(_xlpm.base+_xlpm.fee)/12)),"")} | AY3: {=IFERROR(_xlfn.LET(_xlpm.rate,INDEX('Mutual of Omaha-Graded'!$B$2:$E$37,MATCH($AE3,'Mutual of Omaha-Graded'!$A$2:$A$37,0),IF(LOWER(TRIM($F3))="male",IF(LOWER(TRIM($K3))="yes",2,1),IF(LOWER(TRIM($K3))="yes",4,3))),_xlpm.coverage,VALUE(SUBSTITUTE(SUBSTITUTE($S3,"$",""),",","")),_xlpm.base,_xlpm.rate*(_xlpm.coverage/1000),_xlpm.fee,_xlfn.XLOOKUP("Mutual of Omaha-Graded",Key!$B$1:$U$1,Key!$B$2:$U$2,0),_xlpm.mf,_xlfn.XLOOKUP("Mutual of Omaha-Graded",Key!$B$1:$U$1,Key!$B$3:$U$3,0),IF(_xlpm.mf>0,(_xlpm.base+_xlpm.fee)*_xlpm.mf,(_xlpm.base+_xlpm.fee)/12)),"")} | AZ3: =AP3 | BA3: =IFERROR(IF(AND(AP3>0,AP3<VALUE(SUBSTITUTE(SUBSTITUTE($T3,"$",""),",",""))),VALUE(SUBSTITUTE(SUBSTITUTE($T3,"$",""),",",""))-AP3,""),"") | BB3: =AL3 | BC3: =IFERROR(IF(AND(AL3>0,AL3<VALUE(SUBSTITUTE(SUBSTITUTE($T3,"$",""),",",""))),VALUE(SUBSTITUTE(SUBSTITUTE($T3,"$",""),",",""))-AL3,""),"") | BD3: {=IFERROR(_xlfn.LET(_xlpm.current,VALUE(SUBSTITUTE(SUBSTITUTE($T3,"$",""),",","")),_xlpm.quotes,AF3:AY3,_xlpm.lowest,_xlfn.MINIFS(_xlpm.quotes,_xlpm.quotes,"<"&_xlpm.current,_xlpm.quotes,">0"),IF(_xlpm.lowest="","",SUBSTITUTE(INDEX($AF$1:$AY$1,1,MATCH(_xlpm.lowest,_xlpm.quotes,0))," Monthly Quote",""))),"")} | BE3: {=IFERROR(_xlfn.LET(_xlpm.current,VALUE(SUBSTITUTE(SUBSTITUTE($T3,"$",""),",","")),_xlpm.quotes,AF3:AY3,_xlpm.lowest,_xlfn.MINIFS(_xlpm.quotes,_xlpm.quotes,"<"&_xlpm.current,_xlpm.quotes,">0"),IF(_xlpm.lowest="","",_xlpm.current-_xlpm.lowest)),"")}
A4: Diane R | B4: Patterson | C4: 8189434263 | D4: 75 | E4: 18322 | F4: Female | G4: 9818 Rhea Ave Northridge CA 91324 | H4: NV | I4: 5.7 | J4: 160 | K4: No | L4: dpatte4@dslextreme.com | M4: Cremation | N4: Debbie Coit | O4: Cousin | P4: NA | Q4: NA | R4: Trans America | S4: 5000 | T4: 37.28 | U4: 45992 | V4: 46023 | W4: 567861941 | X4: NA | Y4: Chase Bank | Z4: CVV : 858 Exp : 10/30 | AA4: 4.15e+15 | AB4: Diabieties | AC4: NA | AD4: Dr. Sobiya Khan, DO - | AE4: 76 | AF4: {=IFERROR(_xlfn.LET(_xlpm.rate,INDEX(aflac!$B$2:$E$37,MATCH($AE4,aflac!$A$2:$A$37,0),IF(LOWER(TRIM($F4))="male",IF(LOWER(TRIM($K4))="yes",2,1),IF(LOWER(TRIM($K4))="yes",4,3))),_xlpm.coverage,VALUE(SUBSTITUTE(SUBSTITUTE($S4,"$",""),",","")),_xlpm.base,_xlpm.rate*(_xlpm.coverage/1000),_xlpm.fee,_xlfn.XLOOKUP("aflac",Key!$B$1:$U$1,Key!$B$2:$U$2,0),_xlpm.mf,_xlfn.XLOOKUP("aflac",Key!$B$1:$U$1,Key!$B$3:$U$3,0),IF(_xlpm.mf>0,(_xlpm.base+_xlpm.fee)*_xlpm.mf,(_xlpm.base+_xlpm.fee)/12)),"")} | AG4: {=IFERROR(_xlfn.LET(_xlpm.rate,INDEX('aflac-modified'!$B$2:$C$32,MATCH($AE4,'aflac-modified'!$A$2:$A$32,0),IF(LOWER(TRIM($F4))="male",1,2)),_xlpm.coverage,VALUE(SUBSTITUTE(SUBSTITUTE($S4,"$",""),",","")),_xlpm.base,_xlpm.rate*(_xlpm.coverage/1000),_xlpm.fee,_xlfn.XLOOKUP("aflac-modified",Key!$B$1:$U$1,Key!$B$2:$U$2,0),_xlpm.mf,_xlfn.XLOOKUP("aflac-modified",Key!$B$1:$U$1,Key!$B$3:$U$3,0),IF(_xlpm.mf>0,(_xlpm.base+_xlpm.fee)*_xlpm.mf,(_xlpm.base+_xlpm.fee)/12)),"")} | AH4: {=IFERROR(_xlfn.LET(_xlpm.rate,INDEX(SBLI!$B$2:$E$37,MATCH($AE4,SBLI!$A$2:$A$37,0),IF(LOWER(TRIM($F4))="male",IF(LOWER(TRIM($K4))="yes",2,1),IF(LOWER(TRIM($K4))="yes",4,3))),_xlpm.coverage,VALUE(SUBSTITUTE(SUBSTITUTE($S4,"$",""),",","")),_xlpm.base,_xlpm.rate*(_xlpm.coverage/1000),_xlpm.fee,_xlfn.XLOOKUP("SBLI",Key!$B$1:$U$1,Key!$B$2:$U$2,0),_xlpm.mf,_xlfn.XLOOKUP("SBLI",Key!$B$1:$U$1,Key!$B$3:$U$3,0),IF(_xlpm.mf>0,(_xlpm.base+_xlpm.fee)*_xlpm.mf,(_xlpm.base+_xlpm.fee)/12)),"")} | AI4: {=IFERROR(_xlfn.LET(_xlpm.rate,INDEX('SBLI-Modified'!$B$2:$E$27,MATCH($AE4,'SBLI-Modified'!$A$2:$A$27,0),IF(LOWER(TRIM($F4))="male",IF(LOWER(TRIM($K4))="yes",2,1),IF(LOWER(TRIM($K4))="yes",4,3))),_xlpm.coverage,VALUE(SUBSTITUTE(SUBSTITUTE($S4,"$",""),",","")),_xlpm.base,_xlpm.rate*(_xlpm.coverage/1000),_xlpm.fee,_xlfn.XLOOKUP("SBLI-Modified",Key!$B$1:$U$1,Key!$B$2:$U$2,0),_xlpm.mf,_xlfn.XLOOKUP("SBLI-Modified",Key!$B$1:$U$1,Key!$B$3:$U$3,0),IF(_xlpm.mf>0,(_xlpm.base+_xlpm.fee)*_xlpm.mf,(_xlpm.base+_xlpm.fee)/12)),"")} | AJ4: {=IFERROR(_xlfn.LET(_xlpm.rate,INDEX(CICA!$B$2:$C$42,MATCH($AE4,CICA!$A$2:$A$42,0),IF(LOWER(TRIM($F4))="male",1,2)),_xlpm.coverage,VALUE(SUBSTITUTE(SUBSTITUTE($S4,"$",""),",","")),_xlpm.base,_xlpm.rate*(_xlpm.coverage/1000),_xlpm.fee,_xlfn.XLOOKUP("CICA",Key!$B$1:$U$1,Key!$B$2:$U$2,0),_xlpm.mf,_xlfn.XLOOKUP("CICA",Key!$B$1:$U$1,Key!$B$3:$U$3,0),IF(_xlpm.mf>0,(_xlpm.base+_xlpm.fee)*_xlpm.mf,(_xlpm.base+_xlpm.fee)/12)),"")} | AK4: {=IFERROR(_xlfn.LET(_xlpm.rate,INDEX('CICA-GI'!$B$2:$C$47,MATCH($AE4,'CICA-GI'!$A$2:$A$47,0),IF(LOWER(TRIM($F4))="male",1,2)),_xlpm.coverage,VALUE(SUBSTITUTE(SUBSTITUTE($S4,"$",""),",","")),_xlpm.base,_xlpm.rate*(_xlpm.coverage/1000),_xlpm.fee,_xlfn.XLOOKUP("CICA-GI",Key!$B$1:$U$1,Key!$B$2:$U$2,0),_xlpm.mf,_xlfn.XLOOKUP("CICA-GI",Key!$B$1:$U$1,Key!$B$3:$U$3,0),IF(_xlpm.mf>0,(_xlpm.base+_xlpm.fee)*_xlpm.mf,(_xlpm.base+_xlpm.fee)/12)),"")} | AL4: {=IFERROR(_xlfn.LET(_xlpm.rate,INDEX(gtl!$B$2:$C$52,MATCH($AE4,gtl!$A$2:$A$52,0),IF(LOWER(TRIM($F4))="male",1,2)),_xlpm.coverage,VALUE(SUBSTITUTE(SUBSTITUTE($S4,"$",""),",","")),_xlpm.base,_xlpm.rate*(_xlpm.coverage/1000),_xlpm.fee,_xlfn.XLOOKUP("gtl",Key!$B$1:$U$1,Key!$B$2:$U$2,0),_xlpm.mf,_xlfn.XLOOKUP("gtl",Key!$B$1:$U$1,Key!$B$3:$U$3,0),IF(_xlpm.mf>0,(_xlpm.base+_xlpm.fee)*_xlpm.mf,(_xlpm.base+_xlpm.fee)/12)),"")} | AM4: {=IFERROR(_xlfn.LET(_xlpm.rate,INDEX(TransAmerica!$B$2:$E$69,MATCH($AE4,TransAmerica!$A$2:$A$69,0),IF(LOWER(TRIM($F4))="male",IF(LOWER(TRIM($K4))="yes",2,1),IF(LOWER(TRIM($K4))="yes",4,3))),_xlpm.coverage,VALUE(SUBSTITUTE(SUBSTITUTE($S4,"$",""),",","")),_xlpm.base,_xlpm.rate*(_xlpm.coverage/1000),_xlpm.fee,_xlfn.XLOOKUP("TransAmerica",Key!$B$1:$U$1,Key!$B$2:$U$2,0),_xlpm.mf,_xlfn.XLOOKUP("TransAmerica",Key!$B$1:$U$1,Key!$B$3:$U$3,0),IF(_xlpm.mf>0,(_xlpm.base+_xlpm.fee)*_xlpm.mf,(_xlpm.base+_xlpm.fee)/12)),"")} | AN4: {=IFERROR(_xlfn.LET(_xlpm.rate,INDEX('TransAmerica Graded'!$B$2:$E$64,MATCH($AE4,'TransAmerica Graded'!$A$2:$A$64,0),IF(LOWER(TRIM($F4))="male",IF(LOWER(TRIM($K4))="yes",2,1),IF(LOWER(TRIM($K4))="yes",4,3))),_xlpm.coverage,VALUE(SUBSTITUTE(SUBSTITUTE($S4,"$",""),",","")),_xlpm.base,_xlpm.rate*(_xlpm.coverage/1000),_xlpm.fee,_xlfn.XLOOKUP("TransAmerica Graded",Key!$B$1:$U$1,Key!$B$2:$U$2,0),_xlpm.mf,_xlfn.XLOOKUP("TransAmerica Graded",Key!$B$1:$U$1,Key!$B$3:$U$3,0),IF(_xlpm.mf>0,(_xlpm.base+_xlpm.fee)*_xlpm.mf,(_xlpm.base+_xlpm.fee)/12)),"")} | AO4: {=IFERROR(_xlfn.LET(_xlpm.rate,INDEX(Corebridge!$B$2:$C$32,MATCH($AE4,Corebridge!$A$2:$A$32,0),IF(LOWER(TRIM($F4))="male",1,2)),_xlpm.coverage,VALUE(SUBSTITUTE(SUBSTITUTE($S4,"$",""),",","")),_xlpm.base,_xlpm.rate*(_xlpm.coverage/1000),_xlpm.fee,_xlfn.XLOOKUP("Corebridge",Key!$B$1:$U$1,Key!$B$2:$U$2,0),_xlpm.mf,_xlfn.XLOOKUP("Corebridge",Key!$B$1:$U$1,Key!$B$3:$U$3,0),IF(_xlpm.mf>0,(_xlpm.base+_xlpm.fee)*_xlpm.mf,(_xlpm.base+_xlpm.fee)/12)),"")} | AP4: {=IFERROR(_xlfn.LET(_xlpm.rate,INDEX(amam!$B$2:$E$37,MATCH($AE4,amam!$A$2:$A$37,0),IF(LOWER(TRIM($F4))="male",IF(LOWER(TRIM($K4))="yes",2,1),IF(LOWER(TRIM($K4))="yes",4,3))),_xlpm.coverage,VALUE(SUBSTITUTE(SUBSTITUTE($S4,"$",""),",","")),_xlpm.base,_xlpm.rate*(_xlpm.coverage/1000),_xlpm.fee,_xlfn.XLOOKUP("amam",Key!$B$1:$U$1,Key!$B$2:$U$2,0),_xlpm.mf,_xlfn.XLOOKUP("amam",Key!$B$1:$U$1,Key!$B$3:$U$3,0),IF(_xlpm.mf>0,(_xlpm.base+_xlpm.fee)*_xlpm.mf,(_xlpm.base+_xlpm.fee)/12)),"")} | AQ4: {=IFERROR(_xlfn.LET(_xlpm.rate,INDEX('amam-graded'!$B$2:$E$37,MATCH($AE4,'amam-graded'!$A$2:$A$37,0),IF(LOWER(TRIM($F4))="male",IF(LOWER(TRIM($K4))="yes",2,1),IF(LOWER(TRIM($K4))="yes",4,3))),_xlpm.coverage,VALUE(SUBSTITUTE(SUBSTITUTE($S4,"$",""),",","")),_xlpm.base,_xlpm.rate*(_xlpm.coverage/1000),_xlpm.fee,_xlfn.XLOOKUP("amam-graded",Key!$B$1:$U$1,Key!$B$2:$U$2,0),_xlpm.mf,_xlfn.XLOOKUP("amam-graded",Key!$B$1:$U$1,Key!$B$3:$U$3,0),IF(_xlpm.mf>0,(_xlpm.base+_xlpm.fee)*_xlpm.mf,(_xlpm.base+_xlpm.fee)/12)),"")} | AR4: {=IFERROR(_xlfn.LET(_xlpm.rate,INDEX('amam-return-or-premium'!$B$2:$E$37,MATCH($AE4,'amam-return-or-premium'!$A$2:$A$37,0),IF(LOWER(TRIM($F4))="male",IF(LOWER(TRIM($K4))="yes",2,1),IF(LOWER(TRIM($K4))="yes",4,3))),_xlpm.coverage,VALUE(SUBSTITUTE(SUBSTITUTE($S4,"$",""),",","")),_xlpm.base,_xlpm.rate*(_xlpm.coverage/1000),_xlpm.fee,_xlfn.XLOOKUP("amam-return-or-premium",Key!$B$1:$U$1,Key!$B$2:$U$2,0),_xlpm.mf,_xlfn.XLOOKUP("amam-return-or-premium",Key!$B$1:$U$1,Key!$B$3:$U$3,0),IF(_xlpm.mf>0,(_xlpm.base+_xlpm.fee)*_xlpm.mf,(_xlpm.base+_xlpm.fee)/12)),"")} | AS4: {=IFERROR(_xlfn.LET(_xlpm.rate,INDEX(AHL!$B$2:$E$37,MATCH($AE4,AHL!$A$2:$A$37,0),IF(LOWER(TRIM($F4))="male",IF(LOWER(TRIM($K4))="yes",2,1),IF(LOWER(TRIM($K4))="yes",4,3))),_xlpm.coverage,VALUE(SUBSTITUTE(SUBSTITUTE($S4,"$",""),",","")),_xlpm.base,_xlpm.rate*(_xlpm.coverage/1000),_xlpm.fee,_xlfn.XLOOKUP("AHL",Key!$B$1:$U$1,Key!$B$2:$U$2,0),_xlpm.mf,_xlfn.XLOOKUP("AHL",Key!$B$1:$U$1,Key!$B$3:$U$3,0),IF(_xlpm.mf>0,(_xlpm.base+_xlpm.fee)*_xlpm.mf,(_xlpm.base+_xlpm.fee)/12)),"")} | AT4: {=IFERROR(_xlfn.LET(_xlpm.rate,INDEX('AHL-Graded'!$B$2:$E$32,MATCH($AE4,'AHL-Graded'!$A$2:$A$32,0),IF(LOWER(TRIM($F4))="male",IF(LOWER(TRIM($K4))="yes",2,1),IF(LOWER(TRIM($K4))="yes",4,3))),_xlpm.coverage,VALUE(SUBSTITUTE(SUBSTITUTE($S4,"$",""),",","")),_xlpm.base,_xlpm.rate*(_xlpm.coverage/1000),_xlpm.fee,_xlfn.XLOOKUP("AHL-Graded",Key!$B$1:$U$1,Key!$B$2:$U$2,0),_xlpm.mf,_xlfn.XLOOKUP("AHL-Graded",Key!$B$1:$U$1,Key!$B$3:$U$3,0),IF(_xlpm.mf>0,(_xlpm.base+_xlpm.fee)*_xlpm.mf,(_xlpm.base+_xlpm.fee)/12)),"")} | AU4: {=IFERROR(_xlfn.LET(_xlpm.rate,INDEX('Royal Neighbors'!$B$2:$E$37,MATCH($AE4,'Royal Neighbors'!$A$2:$A$37,0),IF(LOWER(TRIM($F4))="male",IF(LOWER(TRIM($K4))="yes",2,1),IF(LOWER(TRIM($K4))="yes",4,3))),_xlpm.coverage,VALUE(SUBSTITUTE(SUBSTITUTE($S4,"$",""),",","")),_xlpm.base,_xlpm.rate*(_xlpm.coverage/1000),_xlpm.fee,_xlfn.XLOOKUP("Royal Neighbors",Key!$B$1:$U$1,Key!$B$2:$U$2,0),_xlpm.mf,_xlfn.XLOOKUP("Royal Neighbors",Key!$B$1:$U$1,Key!$B$3:$U$3,0),IF(_xlpm.mf>0,(_xlpm.base+_xlpm.fee)*_xlpm.mf,(_xlpm.base+_xlpm.fee)/12)),"")} | AV4: {=IFERROR(_xlfn.LET(_xlpm.rate,INDEX('Royal Neighbors-Graded'!$B$2:$E$37,MATCH($AE4,'Royal Neighbors-Graded'!$A$2:$A$37,0),IF(LOWER(TRIM($F4))="male",IF(LOWER(TRIM($K4))="yes",2,1),IF(LOWER(TRIM($K4))="yes",4,3))),_xlpm.coverage,VALUE(SUBSTITUTE(SUBSTITUTE($S4,"$",""),",","")),_xlpm.base,_xlpm.rate*(_xlpm.coverage/1000),_xlpm.fee,_xlfn.XLOOKUP("Royal Neighbors-Graded",Key!$B$1:$U$1,Key!$B$2:$U$2,0),_xlpm.mf,_xlfn.XLOOKUP("Royal Neighbors-Graded",Key!$B$1:$U$1,Key!$B$3:$U$3,0),IF(_xlpm.mf>0,(_xlpm.base+_xlpm.fee)*_xlpm.mf,(_xlpm.base+_xlpm.fee)/12)),"")} | AW4: {=IFERROR(_xlfn.LET(_xlpm.rate,INDEX('Gerber-GI'!$B$2:$C$32,MATCH($AE4,'Gerber-GI'!$A$2:$A$32,0),IF(LOWER(TRIM($F4))="male",1,2)),_xlpm.coverage,VALUE(SUBSTITUTE(SUBSTITUTE($S4,"$",""),",","")),_xlpm.base,_xlpm.rate*(_xlpm.coverage/1000),_xlpm.fee,_xlfn.XLOOKUP("Gerber-GI",Key!$B$1:$U$1,Key!$B$2:$U$2,0),_xlpm.mf,_xlfn.XLOOKUP("Gerber-GI",Key!$B$1:$U$1,Key!$B$3:$U$3,0),IF(_xlpm.mf>0,(_xlpm.base+_xlpm.fee)*_xlpm.mf,(_xlpm.base+_xlpm.fee)/12)),"")} | AX4: {=IFERROR(_xlfn.LET(_xlpm.rate,INDEX('Mutual of Omaha'!$B$2:$E$42,MATCH($AE4,'Mutual of Omaha'!$A$2:$A$42,0),IF(LOWER(TRIM($F4))="male",IF(LOWER(TRIM($K4))="yes",2,1),IF(LOWER(TRIM($K4))="yes",4,3))),_xlpm.coverage,VALUE(SUBSTITUTE(SUBSTITUTE($S4,"$",""),",","")),_xlpm.base,_xlpm.rate*(_xlpm.coverage/1000),_xlpm.fee,_xlfn.XLOOKUP("Mutal of Omaha",Key!$B$1:$U$1,Key!$B$2:$U$2,0),_xlpm.mf,_xlfn.XLOOKUP("Mutal of Omaha",Key!$B$1:$U$1,Key!$B$3:$U$3,0),IF(_xlpm.mf>0,(_xlpm.base+_xlpm.fee)*_xlpm.mf,(_xlpm.base+_xlpm.fee)/12)),"")} | AY4: {=IFERROR(_xlfn.LET(_xlpm.rate,INDEX('Mutual of Omaha-Graded'!$B$2:$E$37,MATCH($AE4,'Mutual of Omaha-Graded'!$A$2:$A$37,0),IF(LOWER(TRIM($F4))="male",IF(LOWER(TRIM($K4))="yes",2,1),IF(LOWER(TRIM($K4))="yes",4,3))),_xlpm.coverage,VALUE(SUBSTITUTE(SUBSTITUTE($S4,"$",""),",","")),_xlpm.base,_xlpm.rate*(_xlpm.coverage/1000),_xlpm.fee,_xlfn.XLOOKUP("Mutual of Omaha-Graded",Key!$B$1:$U$1,Key!$B$2:$U$2,0),_xlpm.mf,_xlfn.XLOOKUP("Mutual of Omaha-Graded",Key!$B$1:$U$1,Key!$B$3:$U$3,0),IF(_xlpm.mf>0,(_xlpm.base+_xlpm.fee)*_xlpm.mf,(_xlpm.base+_xlpm.fee)/12)),"")} | AZ4: =AP4 | BA4: =IFERROR(IF(AND(AP4>0,AP4<VALUE(SUBSTITUTE(SUBSTITUTE($T4,"$",""),",",""))),VALUE(SUBSTITUTE(SUBSTITUTE($T4,"$",""),",",""))-AP4,""),"") | BB4: =AL4 | BC4: =IFERROR(IF(AND(AL4>0,AL4<VALUE(SUBSTITUTE(SUBSTITUTE($T4,"$",""),",",""))),VALUE(SUBSTITUTE(SUBSTITUTE($T4,"$",""),",",""))-AL4,""),"") | BD4: {=IFERROR(_xlfn.LET(_xlpm.current,VALUE(SUBSTITUTE(SUBSTITUTE($T4,"$",""),",","")),_xlpm.quotes,AF4:AY4,_xlpm.lowest,_xlfn.MINIFS(_xlpm.quotes,_xlpm.quotes,"<"&_xlpm.current,_xlpm.quotes,">0"),IF(_xlpm.lowest="","",SUBSTITUTE(INDEX($AF$1:$AY$1,1,MATCH(_xlpm.lowest,_xlpm.quotes,0))," Monthly Quote",""))),"")} | BE4: {=IFERROR(_xlfn.LET(_xlpm.current,VALUE(SUBSTITUTE(SUBSTITUTE($T4,"$",""),",","")),_xlpm.quotes,AF4:AY4,_xlpm.lowest,_xlfn.MINIFS(_xlpm.quotes,_xlpm.quotes,"<"&_xlpm.current,_xlpm.quotes,">0"),IF(_xlpm.lowest="","",_xlpm.current-_xlpm.lowest)),"")}
A5: Bessie | B5: Kincade | C5: 3149213664 | D5: 76 | E5: 18041 | F5: Female | G5: 14813 Frais Dr Florissant, MO 63034, | H5: MS | I5: 5.4 | J5: 125 | K5: No | L5: NA | M5: Cremation | N5: Arthur Kincade third | O5: Son | P5: Tracey Jackson 06/15/1968 | Q5: Daughter | R5: Senior Life | S5: 7000 | T5: 56.24 | U5: 45994 | V5: 46027 | W5: 486549843 | X5: NA | Y5: First Community Credit Union | Z5: 281081877 | AA5: 12528008 | AB5: NA | AC5: NA | AD5: Yolanda E Bledsoe, MD | AE5: 77 | AF5: {=IFERROR(_xlfn.LET(_xlpm.rate,INDEX(aflac!$B$2:$E$37,MATCH($AE5,aflac!$A$2:$A$37,0),IF(LOWER(TRIM($F5))="male",IF(LOWER(TRIM($K5))="yes",2,1),IF(LOWER(TRIM($K5))="yes",4,3))),_xlpm.coverage,VALUE(SUBSTITUTE(SUBSTITUTE($S5,"$",""),",","")),_xlpm.base,_xlpm.rate*(_xlpm.coverage/1000),_xlpm.fee,_xlfn.XLOOKUP("aflac",Key!$B$1:$U$1,Key!$B$2:$U$2,0),_xlpm.mf,_xlfn.XLOOKUP("aflac",Key!$B$1:$U$1,Key!$B$3:$U$3,0),IF(_xlpm.mf>0,(_xlpm.base+_xlpm.fee)*_xlpm.mf,(_xlpm.base+_xlpm.fee)/12)),"")} | AG5: {=IFERROR(_xlfn.LET(_xlpm.rate,INDEX('aflac-modified'!$B$2:$C$32,MATCH($AE5,'aflac-modified'!$A$2:$A$32,0),IF(LOWER(TRIM($F5))="male",1,2)),_xlpm.coverage,VALUE(SUBSTITUTE(SUBSTITUTE($S5,"$",""),",","")),_xlpm.base,_xlpm.rate*(_xlpm.coverage/1000),_xlpm.fee,_xlfn.XLOOKUP("aflac-modified",Key!$B$1:$U$1,Key!$B$2:$U$2,0),_xlpm.mf,_xlfn.XLOOKUP("aflac-modified",Key!$B$1:$U$1,Key!$B$3:$U$3,0),IF(_xlpm.mf>0,(_xlpm.base+_xlpm.fee)*_xlpm.mf,(_xlpm.base+_xlpm.fee)/12)),"")} | AH5: {=IFERROR(_xlfn.LET(_xlpm.rate,INDEX(SBLI!$B$2:$E$37,MATCH($AE5,SBLI!$A$2:$A$37,0),IF(LOWER(TRIM($F5))="male",IF(LOWER(TRIM($K5))="yes",2,1),IF(LOWER(TRIM($K5))="yes",4,3))),_xlpm.coverage,VALUE(SUBSTITUTE(SUBSTITUTE($S5,"$",""),",","")),_xlpm.base,_xlpm.rate*(_xlpm.coverage/1000),_xlpm.fee,_xlfn.XLOOKUP("SBLI",Key!$B$1:$U$1,Key!$B$2:$U$2,0),_xlpm.mf,_xlfn.XLOOKUP("SBLI",Key!$B$1:$U$1,Key!$B$3:$U$3,0),IF(_xlpm.mf>0,(_xlpm.base+_xlpm.fee)*_xlpm.mf,(_xlpm.base+_xlpm.fee)/12)),"")} | AI5: {=IFERROR(_xlfn.LET(_xlpm.rate,INDEX('SBLI-Modified'!$B$2:$E$27,MATCH($AE5,'SBLI-Modified'!$A$2:$A$27,0),IF(LOWER(TRIM($F5))="male",IF(LOWER(TRIM($K5))="yes",2,1),IF(LOWER(TRIM($K5))="yes",4,3))),_xlpm.coverage,VALUE(SUBSTITUTE(SUBSTITUTE($S5,"$",""),",","")),_xlpm.base,_xlpm.rate*(_xlpm.coverage/1000),_xlpm.fee,_xlfn.XLOOKUP("SBLI-Modified",Key!$B$1:$U$1,Key!$B$2:$U$2,0),_xlpm.mf,_xlfn.XLOOKUP("SBLI-Modified",Key!$B$1:$U$1,Key!$B$3:$U$3,0),IF(_xlpm.mf>0,(_xlpm.base+_xlpm.fee)*_xlpm.mf,(_xlpm.base+_xlpm.fee)/12)),"")} | AJ5: {=IFERROR(_xlfn.LET(_xlpm.rate,INDEX(CICA!$B$2:$C$42,MATCH($AE5,CICA!$A$2:$A$42,0),IF(LOWER(TRIM($F5))="male",1,2)),_xlpm.coverage,VALUE(SUBSTITUTE(SUBSTITUTE($S5,"$",""),",","")),_xlpm.base,_xlpm.rate*(_xlpm.coverage/1000),_xlpm.fee,_xlfn.XLOOKUP("CICA",Key!$B$1:$U$1,Key!$B$2:$U$2,0),_xlpm.mf,_xlfn.XLOOKUP("CICA",Key!$B$1:$U$1,Key!$B$3:$U$3,0),IF(_xlpm.mf>0,(_xlpm.base+_xlpm.fee)*_xlpm.mf,(_xlpm.base+_xlpm.fee)/12)),"")} | AK5: {=IFERROR(_xlfn.LET(_xlpm.rate,INDEX('CICA-GI'!$B$2:$C$47,MATCH($AE5,'CICA-GI'!$A$2:$A$47,0),IF(LOWER(TRIM($F5))="male",1,2)),_xlpm.coverage,VALUE(SUBSTITUTE(SUBSTITUTE($S5,"$",""),",","")),_xlpm.base,_xlpm.rate*(_xlpm.coverage/1000),_xlpm.fee,_xlfn.XLOOKUP("CICA-GI",Key!$B$1:$U$1,Key!$B$2:$U$2,0),_xlpm.mf,_xlfn.XLOOKUP("CICA-GI",Key!$B$1:$U$1,Key!$B$3:$U$3,0),IF(_xlpm.mf>0,(_xlpm.base+_xlpm.fee)*_xlpm.mf,(_xlpm.base+_xlpm.fee)/12)),"")} | AL5: {=IFERROR(_xlfn.LET(_xlpm.rate,INDEX(gtl!$B$2:$C$52,MATCH($AE5,gtl!$A$2:$A$52,0),IF(LOWER(TRIM($F5))="male",1,2)),_xlpm.coverage,VALUE(SUBSTITUTE(SUBSTITUTE($S5,"$",""),",","")),_xlpm.base,_xlpm.rate*(_xlpm.coverage/1000),_xlpm.fee,_xlfn.XLOOKUP("gtl",Key!$B$1:$U$1,Key!$B$2:$U$2,0),_xlpm.mf,_xlfn.XLOOKUP("gtl",Key!$B$1:$U$1,Key!$B$3:$U$3,0),IF(_xlpm.mf>0,(_xlpm.base+_xlpm.fee)*_xlpm.mf,(_xlpm.base+_xlpm.fee)/12)),"")} | AM5: {=IFERROR(_xlfn.LET(_xlpm.rate,INDEX(TransAmerica!$B$2:$E$69,MATCH($AE5,TransAmerica!$A$2:$A$69,0),IF(LOWER(TRIM($F5))="male",IF(LOWER(TRIM($K5))="yes",2,1),IF(LOWER(TRIM($K5))="yes",4,3))),_xlpm.coverage,VALUE(SUBSTITUTE(SUBSTITUTE($S5,"$",""),",","")),_xlpm.base,_xlpm.rate*(_xlpm.coverage/1000),_xlpm.fee,_xlfn.XLOOKUP("TransAmerica",Key!$B$1:$U$1,Key!$B$2:$U$2,0),_xlpm.mf,_xlfn.XLOOKUP("TransAmerica",Key!$B$1:$U$1,Key!$B$3:$U$3,0),IF(_xlpm.mf>0,(_xlpm.base+_xlpm.fee)*_xlpm.mf,(_xlpm.base+_xlpm.fee)/12)),"")} | AN5: {=IFERROR(_xlfn.LET(_xlpm.rate,INDEX('TransAmerica Graded'!$B$2:$E$64,MATCH($AE5,'TransAmerica Graded'!$A$2:$A$64,0),IF(LOWER(TRIM($F5))="male",IF(LOWER(TRIM($K5))="yes",2,1),IF(LOWER(TRIM($K5))="yes",4,3))),_xlpm.coverage,VALUE(SUBSTITUTE(SUBSTITUTE($S5,"$",""),",","")),_xlpm.base,_xlpm.rate*(_xlpm.coverage/1000),_xlpm.fee,_xlfn.XLOOKUP("TransAmerica Graded",Key!$B$1:$U$1,Key!$B$2:$U$2,0),_xlpm.mf,_xlfn.XLOOKUP("TransAmerica Graded",Key!$B$1:$U$1,Key!$B$3:$U$3,0),IF(_xlpm.mf>0,(_xlpm.base+_xlpm.fee)*_xlpm.mf,(_xlpm.base+_xlpm.fee)/12)),"")} | AO5: {=IFERROR(_xlfn.LET(_xlpm.rate,INDEX(Corebridge!$B$2:$C$32,MATCH($AE5,Corebridge!$A$2:$A$32,0),IF(LOWER(TRIM($F5))="male",1,2)),_xlpm.coverage,VALUE(SUBSTITUTE(SUBSTITUTE($S5,"$",""),",","")),_xlpm.base,_xlpm.rate*(_xlpm.coverage/1000),_xlpm.fee,_xlfn.XLOOKUP("Corebridge",Key!$B$1:$U$1,Key!$B$2:$U$2,0),_xlpm.mf,_xlfn.XLOOKUP("Corebridge",Key!$B$1:$U$1,Key!$B$3:$U$3,0),IF(_xlpm.mf>0,(_xlpm.base+_xlpm.fee)*_xlpm.mf,(_xlpm.base+_xlpm.fee)/12)),"")} | AP5: {=IFERROR(_xlfn.LET(_xlpm.rate,INDEX(amam!$B$2:$E$37,MATCH($AE5,amam!$A$2:$A$37,0),IF(LOWER(TRIM($F5))="male",IF(LOWER(TRIM($K5))="yes",2,1),IF(LOWER(TRIM($K5))="yes",4,3))),_xlpm.coverage,VALUE(SUBSTITUTE(SUBSTITUTE($S5,"$",""),",","")),_xlpm.base,_xlpm.rate*(_xlpm.coverage/1000),_xlpm.fee,_xlfn.XLOOKUP("amam",Key!$B$1:$U$1,Key!$B$2:$U$2,0),_xlpm.mf,_xlfn.XLOOKUP("amam",Key!$B$1:$U$1,Key!$B$3:$U$3,0),IF(_xlpm.mf>0,(_xlpm.base+_xlpm.fee)*_xlpm.mf,(_xlpm.base+_xlpm.fee)/12)),"")} | AQ5: {=IFERROR(_xlfn.LET(_xlpm.rate,INDEX('amam-graded'!$B$2:$E$37,MATCH($AE5,'amam-graded'!$A$2:$A$37,0),IF(LOWER(TRIM($F5))="male",IF(LOWER(TRIM($K5))="yes",2,1),IF(LOWER(TRIM($K5))="yes",4,3))),_xlpm.coverage,VALUE(SUBSTITUTE(SUBSTITUTE($S5,"$",""),",","")),_xlpm.base,_xlpm.rate*(_xlpm.coverage/1000),_xlpm.fee,_xlfn.XLOOKUP("amam-graded",Key!$B$1:$U$1,Key!$B$2:$U$2,0),_xlpm.mf,_xlfn.XLOOKUP("amam-graded",Key!$B$1:$U$1,Key!$B$3:$U$3,0),IF(_xlpm.mf>0,(_xlpm.base+_xlpm.fee)*_xlpm.mf,(_xlpm.base+_xlpm.fee)/12)),"")} | AR5: {=IFERROR(_xlfn.LET(_xlpm.rate,INDEX('amam-return-or-premium'!$B$2:$E$37,MATCH($AE5,'amam-return-or-premium'!$A$2:$A$37,0),IF(LOWER(TRIM($F5))="male",IF(LOWER(TRIM($K5))="yes",2,1),IF(LOWER(TRIM($K5))="yes",4,3))),_xlpm.coverage,VALUE(SUBSTITUTE(SUBSTITUTE($S5,"$",""),",","")),_xlpm.base,_xlpm.rate*(_xlpm.coverage/1000),_xlpm.fee,_xlfn.XLOOKUP("amam-return-or-premium",Key!$B$1:$U$1,Key!$B$2:$U$2,0),_xlpm.mf,_xlfn.XLOOKUP("amam-return-or-premium",Key!$B$1:$U$1,Key!$B$3:$U$3,0),IF(_xlpm.mf>0,(_xlpm.base+_xlpm.fee)*_xlpm.mf,(_xlpm.base+_xlpm.fee)/12)),"")} | AS5: {=IFERROR(_xlfn.LET(_xlpm.rate,INDEX(AHL!$B$2:$E$37,MATCH($AE5,AHL!$A$2:$A$37,0),IF(LOWER(TRIM($F5))="male",IF(LOWER(TRIM($K5))="yes",2,1),IF(LOWER(TRIM($K5))="yes",4,3))),_xlpm.coverage,VALUE(SUBSTITUTE(SUBSTITUTE($S5,"$",""),",","")),_xlpm.base,_xlpm.rate*(_xlpm.coverage/1000),_xlpm.fee,_xlfn.XLOOKUP("AHL",Key!$B$1:$U$1,Key!$B$2:$U$2,0),_xlpm.mf,_xlfn.XLOOKUP("AHL",Key!$B$1:$U$1,Key!$B$3:$U$3,0),IF(_xlpm.mf>0,(_xlpm.base+_xlpm.fee)*_xlpm.mf,(_xlpm.base+_xlpm.fee)/12)),"")} | AT5: {=IFERROR(_xlfn.LET(_xlpm.rate,INDEX('AHL-Graded'!$B$2:$E$32,MATCH($AE5,'AHL-Graded'!$A$2:$A$32,0),IF(LOWER(TRIM($F5))="male",IF(LOWER(TRIM($K5))="yes",2,1),IF(LOWER(TRIM($K5))="yes",4,3))),_xlpm.coverage,VALUE(SUBSTITUTE(SUBSTITUTE($S5,"$",""),",","")),_xlpm.base,_xlpm.rate*(_xlpm.coverage/1000),_xlpm.fee,_xlfn.XLOOKUP("AHL-Graded",Key!$B$1:$U$1,Key!$B$2:$U$2,0),_xlpm.mf,_xlfn.XLOOKUP("AHL-Graded",Key!$B$1:$U$1,Key!$B$3:$U$3,0),IF(_xlpm.mf>0,(_xlpm.base+_xlpm.fee)*_xlpm.mf,(_xlpm.base+_xlpm.fee)/12)),"")} | AU5: {=IFERROR(_xlfn.LET(_xlpm.rate,INDEX('Royal Neighbors'!$B$2:$E$37,MATCH($AE5,'Royal Neighbors'!$A$2:$A$37,0),IF(LOWER(TRIM($F5))="male",IF(LOWER(TRIM($K5))="yes",2,1),IF(LOWER(TRIM($K5))="yes",4,3))),_xlpm.coverage,VALUE(SUBSTITUTE(SUBSTITUTE($S5,"$",""),",","")),_xlpm.base,_xlpm.rate*(_xlpm.coverage/1000),_xlpm.fee,_xlfn.XLOOKUP("Royal Neighbors",Key!$B$1:$U$1,Key!$B$2:$U$2,0),_xlpm.mf,_xlfn.XLOOKUP("Royal Neighbors",Key!$B$1:$U$1,Key!$B$3:$U$3,0),IF(_xlpm.mf>0,(_xlpm.base+_xlpm.fee)*_xlpm.mf,(_xlpm.base+_xlpm.fee)/12)),"")} | AV5: {=IFERROR(_xlfn.LET(_xlpm.rate,INDEX('Royal Neighbors-Graded'!$B$2:$E$37,MATCH($AE5,'Royal Neighbors-Graded'!$A$2:$A$37,0),IF(LOWER(TRIM($F5))="male",IF(LOWER(TRIM($K5))="yes",2,1),IF(LOWER(TRIM($K5))="yes",4,3))),_xlpm.coverage,VALUE(SUBSTITUTE(SUBSTITUTE($S5,"$",""),",","")),_xlpm.base,_xlpm.rate*(_xlpm.coverage/1000),_xlpm.fee,_xlfn.XLOOKUP("Royal Neighbors-Graded",Key!$B$1:$U$1,Key!$B$2:$U$2,0),_xlpm.mf,_xlfn.XLOOKUP("Royal Neighbors-Graded",Key!$B$1:$U$1,Key!$B$3:$U$3,0),IF(_xlpm.mf>0,(_xlpm.base+_xlpm.fee)*_xlpm.mf,(_xlpm.base+_xlpm.fee)/12)),"")} | AW5: {=IFERROR(_xlfn.LET(_xlpm.rate,INDEX('Gerber-GI'!$B$2:$C$32,MATCH($AE5,'Gerber-GI'!$A$2:$A$32,0),IF(LOWER(TRIM($F5))="male",1,2)),_xlpm.coverage,VALUE(SUBSTITUTE(SUBSTITUTE($S5,"$",""),",","")),_xlpm.base,_xlpm.rate*(_xlpm.coverage/1000),_xlpm.fee,_xlfn.XLOOKUP("Gerber-GI",Key!$B$1:$U$1,Key!$B$2:$U$2,0),_xlpm.mf,_xlfn.XLOOKUP("Gerber-GI",Key!$B$1:$U$1,Key!$B$3:$U$3,0),IF(_xlpm.mf>0,(_xlpm.base+_xlpm.fee)*_xlpm.mf,(_xlpm.base+_xlpm.fee)/12)),"")} | AX5: {=IFERROR(_xlfn.LET(_xlpm.rate,INDEX('Mutual of Omaha'!$B$2:$E$42,MATCH($AE5,'Mutual of Omaha'!$A$2:$A$42,0),IF(LOWER(TRIM($F5))="male",IF(LOWER(TRIM($K5))="yes",2,1),IF(LOWER(TRIM($K5))="yes",4,3))),_xlpm.coverage,VALUE(SUBSTITUTE(SUBSTITUTE($S5,"$",""),",","")),_xlpm.base,_xlpm.rate*(_xlpm.coverage/1000),_xlpm.fee,_xlfn.XLOOKUP("Mutal of Omaha",Key!$B$1:$U$1,Key!$B$2:$U$2,0),_xlpm.mf,_xlfn.XLOOKUP("Mutal of Omaha",Key!$B$1:$U$1,Key!$B$3:$U$3,0),IF(_xlpm.mf>0,(_xlpm.base+_xlpm.fee)*_xlpm.mf,(_xlpm.base+_xlpm.fee)/12)),"")} | AY5: {=IFERROR(_xlfn.LET(_xlpm.rate,INDEX('Mutual of Omaha-Graded'!$B$2:$E$37,MATCH($AE5,'Mutual of Omaha-Graded'!$A$2:$A$37,0),IF(LOWER(TRIM($F5))="male",IF(LOWER(TRIM($K5))="yes",2,1),IF(LOWER(TRIM($K5))="yes",4,3))),_xlpm.coverage,VALUE(SUBSTITUTE(SUBSTITUTE($S5,"$",""),",","")),_xlpm.base,_xlpm.rate*(_xlpm.coverage/1000),_xlpm.fee,_xlfn.XLOOKUP("Mutual of Omaha-Graded",Key!$B$1:$U$1,Key!$B$2:$U$2,0),_xlpm.mf,_xlfn.XLOOKUP("Mutual of Omaha-Graded",Key!$B$1:$U$1,Key!$B$3:$U$3,0),IF(_xlpm.mf>0,(_xlpm.base+_xlpm.fee)*_xlpm.mf,(_xlpm.base+_xlpm.fee)/12)),"")} | AZ5: =AP5 | BA5: =IFERROR(IF(AND(AP5>0,AP5<VALUE(SUBSTITUTE(SUBSTITUTE($T5,"$",""),",",""))),VALUE(SUBSTITUTE(SUBSTITUTE($T5,"$",""),",",""))-AP5,""),"") | BB5: =AL5 | BC5: =IFERROR(IF(AND(AL5>0,AL5<VALUE(SUBSTITUTE(SUBSTITUTE($T5,"$",""),",",""))),VALUE(SUBSTITUTE(SUBSTITUTE($T5,"$",""),",",""))-AL5,""),"") | BD5: {=IFERROR(_xlfn.LET(_xlpm.current,VALUE(SUBSTITUTE(SUBSTITUTE($T5,"$",""),",","")),_xlpm.quotes,AF5:AY5,_xlpm.lowest,_xlfn.MINIFS(_xlpm.quotes,_xlpm.quotes,"<"&_xlpm.current,_xlpm.quotes,">0"),IF(_xlpm.lowest="","",SUBSTITUTE(INDEX($AF$1:$AY$1,1,MATCH(_xlpm.lowest,_xlpm.quotes,0))," Monthly Quote",""))),"")} | BE5: {=IFERROR(_xlfn.LET(_xlpm.current,VALUE(SUBSTITUTE(SUBSTITUTE($T5,"$",""),",","")),_xlpm.quotes,AF5:AY5,_xlpm.lowest,_xlfn.MINIFS(_xlpm.quotes,_xlpm.quotes,"<"&_xlpm.current,_xlpm.quotes,">0"),IF(_xlpm.lowest="","",_xlpm.current-_xlpm.lowest)),"")}
A6: Nancy | B6: Franzwa | C6: 8159620911 | D6: 84 | E6: 1941-11-16 | F6: Female | K6: No | R6: Transamerica | S6: 2500 | T6: 48.64 | U6: 2025-11-20 | AE6: 84 | AF6: {=IFERROR(_xlfn.LET(_xlpm.rate,INDEX(aflac!$B$2:$E$37,MATCH($AE6,aflac!$A$2:$A$37,0),IF(LOWER(TRIM($F6))="male",IF(LOWER(TRIM($K6))="yes",2,1),IF(LOWER(TRIM($K6))="yes",4,3))),_xlpm.coverage,VALUE(SUBSTITUTE(SUBSTITUTE($S6,"$",""),",","")),_xlpm.base,_xlpm.rate*(_xlpm.coverage/1000),_xlpm.fee,_xlfn.XLOOKUP("aflac",Key!$B$1:$U$1,Key!$B$2:$U$2,0),_xlpm.mf,_xlfn.XLOOKUP("aflac",Key!$B$1:$U$1,Key!$B$3:$U$3,0),IF(_xlpm.mf>0,(_xlpm.base+_xlpm.fee)*_xlpm.mf,(_xlpm.base+_xlpm.fee)/12)),"")} | AG6: {=IFERROR(_xlfn.LET(_xlpm.rate,INDEX('aflac-modified'!$B$2:$C$32,MATCH($AE6,'aflac-modified'!$A$2:$A$32,0),IF(LOWER(TRIM($F6))="male",1,2)),_xlpm.coverage,VALUE(SUBSTITUTE(SUBSTITUTE($S6,"$",""),",","")),_xlpm.base,_xlpm.rate*(_xlpm.coverage/1000),_xlpm.fee,_xlfn.XLOOKUP("aflac-modified",Key!$B$1:$U$1,Key!$B$2:$U$2,0),_xlpm.mf,_xlfn.XLOOKUP("aflac-modified",Key!$B$1:$U$1,Key!$B$3:$U$3,0),IF(_xlpm.mf>0,(_xlpm.base+_xlpm.fee)*_xlpm.mf,(_xlpm.base+_xlpm.fee)/12)),"")} | AH6: 53.14 | AI6: {=IFERROR(_xlfn.LET(_xlpm.rate,INDEX('SBLI-Modified'!$B$2:$E$27,MATCH($AE6,'SBLI-Modified'!$A$2:$A$27,0),IF(LOWER(TRIM($F6))="male",IF(LOWER(TRIM($K6))="yes",2,1),IF(LOWER(TRIM($K6))="yes",4,3))),_xlpm.coverage,VALUE(SUBSTITUTE(SUBSTITUTE($S6,"$",""),",","")),_xlpm.base,_xlpm.rate*(_xlpm.coverage/1000),_xlpm.fee,_xlfn.XLOOKUP("SBLI-Modified",Key!$B$1:$U$1,Key!$B$2:$U$2,0),_xlpm.mf,_xlfn.XLOOKUP("SBLI-Modified",Key!$B$1:$U$1,Key!$B$3:$U$3,0),IF(_xlpm.mf>0,(_xlpm.base+_xlpm.fee)*_xlpm.mf,(_xlpm.base+_xlpm.fee)/12)),"")} | AJ6: 48.04 | AK6: 48.04 | AL6: 56.08 | AM6: 51.18 | AN6: 51.18 | AO6: {=IFERROR(_xlfn.LET(_xlpm.rate,INDEX(Corebridge!$B$2:$C$32,MATCH($AE6,Corebridge!$A$2:$A$32,0),IF(LOWER(TRIM($F6))="male",1,2)),_xlpm.coverage,VALUE(SUBSTITUTE(SUBSTITUTE($S6,"$",""),",","")),_xlpm.base,_xlpm.rate*(_xlpm.coverage/1000),_xlpm.fee,_xlfn.XLOOKUP("Corebridge",Key!$B$1:$U$1,Key!$B$2:$U$2,0),_xlpm.mf,_xlfn.XLOOKUP("Corebridge",Key!$B$1:$U$1,Key!$B$3:$U$3,0),IF(_xlpm.mf>0,(_xlpm.base+_xlpm.fee)*_xlpm.mf,(_xlpm.base+_xlpm.fee)/12)),"")} | AP6: 40.26 | AQ6: 40.26 | AR6: 40.26 | AS6: 50.77 | AT6: 50.77 | AU6: 37.23 | AV6: 37.23 | AW6: {=IFERROR(_xlfn.LET(_xlpm.rate,INDEX('Gerber-GI'!$B$2:$C$32,MATCH($AE6,'Gerber-GI'!$A$2:$A$32,0),IF(LOWER(TRIM($F6))="male",1,2)),_xlpm.coverage,VALUE(SUBSTITUTE(SUBSTITUTE($S6,"$",""),",","")),_xlpm.base,_xlpm.rate*(_xlpm.coverage/1000),_xlpm.fee,_xlfn.XLOOKUP("Gerber-GI",Key!$B$1:$U$1,Key!$B$2:$U$2,0),_xlpm.mf,_xlfn.XLOOKUP("Gerber-GI",Key!$B$1:$U$1,Key!$B$3:$U$3,0),IF(_xlpm.mf>0,(_xlpm.base+_xlpm.fee)*_xlpm.mf,(_xlpm.base+_xlpm.fee)/12)),"")} | AX6: 34.54 | AY6: 34.54 | AZ6: 40.26 | BA6: 8.38 | BB6: 56.08 | BC6: =IFERROR(IF(AND(AL6>0,AL6<VALUE(SUBSTITUTE(SUBSTITUTE($T6,"$",""),",",""))),VALUE(SUBSTITUTE(SUBSTITUTE($T6,"$",""),",",""))-AL6,""),"") | BD6: Mutual of Omaha | BE6: 14.1
